<sdf version='1.9'>
  <model name='aubo_i10'>
    <joint name='world_joint' type='fixed'>
      <pose relative_to='__model__'>0 0 0 0 0 0</pose>
      <parent>world</parent>
      <child>base_link</child>
    </joint>
    <link name='base_link'>
      <pose relative_to='world_joint'>0 0 0 0 0 0</pose>
      <inertial>
        <pose>0.000136 0.001601 0.018986 0 0 0</pose>
        <mass>2.5920000000000001</mass>
        <inertia>
          <ixx>0.0085240000000000003</ixx>
          <ixy>-9.9999999999999995e-07</ixy>
          <ixz>-5.0000000000000004e-06</ixz>
          <iyy>0.0079340000000000001</iyy>
          <iyz>-8.1000000000000004e-05</iyz>
          <izz>0.015304</izz>
        </inertia>
      </inertial>
      <collision name='base_link_collision'>
        <pose>0 0 0 0 0 0</pose>
        <geometry>
          <mesh>
            <scale>1 1 1</scale>
            <uri>file:///home/xvshuo/work/scl/auborobot/install/share/aubo_description/meshes/aubo_i10/collision/link0.STL</uri>
          </mesh>
        </geometry>
      </collision>
      <visual name='base_link_visual'>
        <pose>0 0 0 0 0 0</pose>
        <geometry>
          <mesh>
            <scale>1 1 1</scale>
            <uri>file:///home/xvshuo/work/scl/auborobot/install/share/aubo_description/meshes/aubo_i10/visual/link0.DAE</uri>
          </mesh>
        </geometry>
        <material>
          <diffuse>1 1 1 1</diffuse>
          <ambient>1 1 1 1</ambient>
        </material>
      </visual>
    </link>
    <joint name='shoulder_joint' type='revolute'>
      <pose relative_to='base_link'>0 0 0.1632 0 0 3.141592653589793</pose>
      <parent>base_link</parent>
      <child>shoulder_Link</child>
      <axis>
        <xyz>0 0 1</xyz>
        <limit>
          <lower>-6.2831853071795862</lower>
          <upper>6.2831853071795862</upper>
          <effort>267</effort>
          <velocity>3.1415999999999999</velocity>
        </limit>
        <dynamics>
          <spring_reference>0</spring_reference>
          <spring_stiffness>0</spring_stiffness>
        </dynamics>
      </axis>
    </joint>
    <link name='shoulder_Link'>
      <pose relative_to='shoulder_joint'>0 0 0 0 0 0</pose>
      <inertial>
        <pose>-4e-06 0.005112 -0.026275 0 0 0</pose>
        <mass>10.180139</mass>
        <inertia>
          <ixx>0.043326000000000003</ixx>
          <ixy>3.0000000000000001e-06</ixy>
          <ixz>3.0000000000000001e-06</ixz>
          <iyy>0.042233</iyy>
          <iyz>-0.0017669999999999999</iyz>
          <izz>0.029902000000000001</izz>
        </inertia>
      </inertial>
      <collision name='shoulder_Link_collision'>
        <pose>0 0 0 0 0 0</pose>
        <geometry>
          <mesh>
            <scale>1 1 1</scale>
            <uri>file:///home/xvshuo/work/scl/auborobot/install/share/aubo_description/meshes/aubo_i10/collision/link1.STL</uri>
          </mesh>
        </geometry>
      </collision>
      <visual name='shoulder_Link_visual'>
        <pose>0 0 0 0 0 0</pose>
        <geometry>
          <mesh>
            <scale>1 1 1</scale>
            <uri>file:///home/xvshuo/work/scl/auborobot/install/share/aubo_description/meshes/aubo_i10/visual/link1.DAE</uri>
          </mesh>
        </geometry>
        <material>
          <diffuse>1 1 1 1</diffuse>
          <ambient>1 1 1 1</ambient>
        </material>
      </visual>
    </link>
    <joint name='upperArm_joint' type='revolute'>
      <pose relative_to='shoulder_Link'>0 0.2013 0 -1.570796326794896 -1.570796326794897 0</pose>
      <parent>shoulder_Link</parent>
      <child>upperArm_Link</child>
      <axis>
        <xyz>0 0 1</xyz>
        <limit>
          <lower>-6.2831853071795862</lower>
          <upper>6.2831853071795862</upper>
          <effort>267</effort>
          <velocity>3.1415999999999999</velocity>
        </limit>
        <dynamics>
          <spring_reference>0</spring_reference>
          <spring_stiffness>0</spring_stiffness>
        </dynamics>
      </axis>
    </joint>
    <link name='upperArm_Link'>
      <pose relative_to='upperArm_joint'>0 0 0 0 0 0</pose>
      <inertial>
        <pose>0.231117 -1.3e-05 -0.022852 0 0 0</pose>
        <mass>18.096361000000002</mass>
        <inertia>
          <ixx>0.064904000000000003</ixx>
          <ixy>3.0000000000000001e-05</ixy>
          <ixz>-0.033710999999999998</ixz>
          <iyy>1.5246230000000001</iyy>
          <iyz>1.5e-05</iyz>
          <izz>1.5056639999999999</izz>
        </inertia>
      </inertial>
      <collision name='upperArm_Link_collision'>
        <pose>0 0 0 0 0 0</pose>
        <geometry>
          <mesh>
            <scale>1 1 1</scale>
            <uri>file:///home/xvshuo/work/scl/auborobot/install/share/aubo_description/meshes/aubo_i10/collision/link2.STL</uri>
          </mesh>
        </geometry>
      </collision>
      <visual name='upperArm_Link_visual'>
        <pose>0 0 0 0 0 0</pose>
        <geometry>
          <mesh>
            <scale>1 1 1</scale>
            <uri>file:///home/xvshuo/work/scl/auborobot/install/share/aubo_description/meshes/aubo_i10/visual/link2.DAE</uri>
          </mesh>
        </geometry>
        <material>
          <diffuse>1 1 1 1</diffuse>
          <ambient>1 1 1 1</ambient>
        </material>
      </visual>
    </link>
    <joint name='foreArm_joint' type='revolute'>
      <pose relative_to='upperArm_Link'>0.647 0 0 -3.141592653589793 0 0</pose>
      <parent>upperArm_Link</parent>
      <child>foreArm_Link</child>
      <axis>
        <xyz>0 0 1</xyz>
        <limit>
          <lower>-6.2831853071795862</lower>
          <upper>6.2831853071795862</upper>
          <effort>133</effort>
          <velocity>2.5655999999999999</velocity>
        </limit>
        <dynamics>
          <spring_reference>0</spring_reference>
          <spring_stiffness>0</spring_stiffness>
        </dynamics>
      </axis>
    </joint>
    <link name='foreArm_Link'>
      <pose relative_to='foreArm_joint'>0 0 0 0 0 0</pose>
      <inertial>
        <pose>0.41956 -1.9e-05 0.118053 0 0 0</pose>
        <mass>4.4480919999999999</mass>
        <inertia>
          <ixx>0.0067990000000000004</ixx>
          <ixy>1.5999999999999999e-05</ixy>
          <ixz>0.0040039999999999997</ixz>
          <iyy>0.246194</iyy>
          <iyz>5.0000000000000004e-06</iyz>
          <izz>0.24479000000000001</izz>
        </inertia>
      </inertial>
      <collision name='foreArm_Link_collision'>
        <pose>0 0 0 0 0 0</pose>
        <geometry>
          <mesh>
            <scale>1 1 1</scale>
            <uri>file:///home/xvshuo/work/scl/auborobot/install/share/aubo_description/meshes/aubo_i10/collision/link3.STL</uri>
          </mesh>
        </geometry>
      </collision>
      <visual name='foreArm_Link_visual'>
        <pose>0 0 0 0 0 0</pose>
        <geometry>
          <mesh>
            <scale>1 1 1</scale>
            <uri>file:///home/xvshuo/work/scl/auborobot/install/share/aubo_description/meshes/aubo_i10/visual/link3.DAE</uri>
          </mesh>
        </geometry>
        <material>
          <diffuse>1 1 1 1</diffuse>
          <ambient>1 1 1 1</ambient>
        </material>
      </visual>
    </link>
    <joint name='wrist1_joint' type='revolute'>
      <pose relative_to='foreArm_Link'>0.6005 0 0 3.141592653589793 0 1.570796326794896</pose>
      <parent>foreArm_Link</parent>
      <child>wrist1_Link</child>
      <axis>
        <xyz>0 0 1</xyz>
        <limit>
          <lower>-6.2831853071795862</lower>
          <upper>6.2831853071795862</upper>
          <effort>49</effort>
          <velocity>3.1415999999999999</velocity>
        </limit>
        <dynamics>
          <spring_reference>0</spring_reference>
          <spring_stiffness>0</spring_stiffness>
        </dynamics>
      </axis>
    </joint>
    <link name='wrist1_Link'>
      <pose relative_to='wrist1_joint'>0 0 0 0 0 0</pose>
      <inertial>
        <pose>4.7e-05 0.009773 -0.005726 0 0 0</pose>
        <mass>1.79166</mass>
        <inertia>
          <ixx>0.002457</ixx>
          <ixy>3.9999999999999998e-06</ixy>
          <ixz>9.9999999999999995e-07</ixz>
          <iyy>0.0015900000000000001</iyy>
          <iyz>-0.00012300000000000001</iyz>
          <izz>0.002183</izz>
        </inertia>
      </inertial>
      <collision name='wrist1_Link_collision'>
        <pose>0 0 0 0 0 0</pose>
        <geometry>
          <mesh>
            <scale>1 1 1</scale>
            <uri>file:///home/xvshuo/work/scl/auborobot/install/share/aubo_description/meshes/aubo_i10/collision/link4.STL</uri>
          </mesh>
        </geometry>
      </collision>
      <visual name='wrist1_Link_visual'>
        <pose>0 0 0 0 0 0</pose>
        <geometry>
          <mesh>
            <scale>1 1 1</scale>
            <uri>file:///home/xvshuo/work/scl/auborobot/install/share/aubo_description/meshes/aubo_i10/visual/link4.DAE</uri>
          </mesh>
        </geometry>
        <material>
          <diffuse>1 1 1 1</diffuse>
          <ambient>1 1 1 1</ambient>
        </material>
      </visual>
    </link>
    <joint name='wrist2_joint' type='revolute'>
      <pose relative_to='wrist1_Link'>0 0.1025 0 -1.570796326794896 0 0</pose>
      <parent>wrist1_Link</parent>
      <child>wrist2_Link</child>
      <axis>
        <xyz>0 0 1</xyz>
        <limit>
          <lower>-6.2831853071795862</lower>
          <upper>6.2831853071795862</upper>
          <effort>13.5</effort>
          <velocity>3.1415999999999999</velocity>
        </limit>
        <dynamics>
          <spring_reference>0</spring_reference>
          <spring_stiffness>0</spring_stiffness>
        </dynamics>
      </axis>
    </joint>
    <link name='wrist2_Link'>
      <pose relative_to='wrist2_joint'>0 0 0 0 0 0</pose>
      <inertial>
        <pose>-3.8e-05 -0.011278 -0.001539 0 0 0</pose>
        <mass>1.6280220000000001</mass>
        <inertia>
          <ixx>0.001951</ixx>
          <ixy>3.0000000000000001e-06</ixy>
          <ixz>-9.9999999999999995e-07</ixz>
          <iyy>0.0011540000000000001</iyy>
          <iyz>4.1999999999999998e-05</iyz>
          <izz>0.001931</izz>
        </inertia>
      </inertial>
      <collision name='wrist2_Link_collision'>
        <pose>0 0 0 0 0 0</pose>
        <geometry>
          <mesh>
            <scale>1 1 1</scale>
            <uri>file:///home/xvshuo/work/scl/auborobot/install/share/aubo_description/meshes/aubo_i10/collision/link5.STL</uri>
          </mesh>
        </geometry>
      </collision>
      <visual name='wrist2_Link_visual'>
        <pose>0 0 0 0 0 0</pose>
        <geometry>
          <mesh>
            <scale>1 1 1</scale>
            <uri>file:///home/xvshuo/work/scl/auborobot/install/share/aubo_description/meshes/aubo_i10/visual/link5.DAE</uri>
          </mesh>
        </geometry>
        <material>
          <diffuse>1 1 1 1</diffuse>
          <ambient>1 1 1 1</ambient>
        </material>
      </visual>
    </link>
    <joint name='wrist3_joint' type='revolute'>
      <pose relative_to='wrist2_Link'>0 -0.094 0 1.570796326794896 0 0</pose>
      <parent>wrist2_Link</parent>
      <child>wrist3_Link</child>
      <axis>
        <xyz>0 0 1</xyz>
        <limit>
          <lower>-6.2831853071795862</lower>
          <upper>6.2831853071795862</upper>
          <effort>13.5</effort>
          <velocity>3.1415999999999999</velocity>
        </limit>
        <dynamics>
          <spring_reference>0</spring_reference>
          <spring_stiffness>0</spring_stiffness>
        </dynamics>
      </axis>
    </joint>
    <link name='wrist3_Link'>
      <pose relative_to='wrist3_joint'>0 0 0 0 0 0</pose>
      <inertial>
        <pose>2.2e-05 0.0005999999999999999 -0.017081 0 0 0</pose>
        <mass>0.1978</mass>
        <inertia>
          <ixx>0.000118</ixx>
          <ixy>0</ixy>
          <ixz>0</ixz>
          <iyy>0.000112</iyy>
          <iyz>9.9999999999999995e-07</iyz>
          <izz>0.000184</izz>
        </inertia>
      </inertial>
      <collision name='wrist3_Link_collision'>
        <pose>0 0 0 0 0 0</pose>
        <geometry>
          <mesh>
            <scale>1 1 1</scale>
            <uri>file:///home/xvshuo/work/scl/auborobot/install/share/aubo_description/meshes/aubo_i10/collision/link6.STL</uri>
          </mesh>
        </geometry>
      </collision>
      <visual name='wrist3_Link_visual'>
        <pose>0 0 0 0 0 0</pose>
        <geometry>
          <mesh>
            <scale>1 1 1</scale>
            <uri>file:///home/xvshuo/work/scl/auborobot/install/share/aubo_description/meshes/aubo_i10/visual/link6.DAE</uri>
          </mesh>
        </geometry>
        <material>
          <diffuse>1 1 1 1</diffuse>
          <ambient>1 1 1 1</ambient>
        </material>
      </visual>
    </link>

    <!-- 相机链接 -->
    <link name='camera_link'>
      <pose relative_to='wrist3_Link'>0 0 0.01 0 0 0</pose>      <!-- 相机位置和方向相对于 wrist3_Link -->
      <inertial>
        <mass>0.1</mass>
        <inertia>
          <ixx>0.0001</ixx>
          <iyy>0.0001</iyy>
          <izz>0.0001</izz>
        </inertia>
      </inertial>
      <collision name='camera_collision'>
        <geometry>
          <cylinder>
            <radius>0.03</radius>            <!-- 底部的半径 -->
            <length>0.05</length>            <!-- 圆柱的高度 -->
          </cylinder>
        </geometry>
      </collision>
      <visual name='camera_visual_base'>
        <pose>0 0 0 0 0 0</pose>
        <geometry>
          <cylinder>
            <radius>0.03</radius>            <!-- 底部的半径 -->
            <length>0.03</length>            <!-- 底部圆柱的高度 -->
          </cylinder>
        </geometry>
        <material>
          <diffuse>0.7 0.7 0.7 1</diffuse>
        </material>
      </visual>
      <visual name='camera_visual_top'>
        <pose>0 0 0.03 0 0 0</pose>        <!-- 顶部部分的相对位置 -->
        <geometry>
          <cylinder>
            <radius>0.02</radius>            <!-- 顶部的半径 -->
            <length>0.02</length>            <!-- 顶部圆柱的高度 -->
          </cylinder>
        </geometry>
        <material>
          <diffuse>0.7 0.7 0.7 1</diffuse>
        </material>
      </visual>
      <sensor name='camera' type='camera'>
        <pose>0 0 0.05 -1.57080 -1.5708 0</pose>        <!-- 相机的光学中心位置 -->
        <camera>
          <horizontal_fov>1.047</horizontal_fov>
          <image>
            <width>800</width>
            <height>600</height>
          </image>
          <clip>
            <near>0.1</near>
            <far>100</far>
          </clip>
        </camera>
        <always_on>1</always_on>
        <update_rate>15</update_rate>
        <visualize>true</visualize>
        <topic>/camera</topic>
      </sensor>
    </link>

    <!-- 将相机链接固定在机器人末端执行器上 -->
    <joint name='camera_joint' type='fixed'>
      <parent>wrist3_Link</parent>
      <child>camera_link</child>
      <pose>0 0 0 0 0 0</pose>
    </joint>

    <!-- 相机插件 -->
    <plugin filename="ignition-gazebo-sensors-system" name="gz::sim::systems::Sensors">
      <render_engine>ogre</render_engine>
    </plugin>

    <plugin name='ign_ros2_control::IgnitionROS2ControlPlugin' filename='ign_ros2_control-system'>
      <parameters>/home/xvshuo/work/scl/gazebo_moviet2/src/aubo_moveit_config/config/ros2_controllers.yaml</parameters>
    </plugin>
  </model>
</sdf>
